Workbook

Sheet Phases
A1: No | B1: Name | C1: WorkType | D1: EAAct | E1: NumberOfDays | F1: Legislated | G1: Color | H1: Visibility | I1: SortOrder
A2: 1 | B2: Notification Intake | C2: Project Notification | D2: EA Act (2018) | E2: 21 | F2: =FALSE() -> FALSE | G2: #3eb1d7 | H2: REGULAR | I2: 1
A3: 2 | B3: Notification Review | C3: Project Notification | D3: EA Act (2018) | E3: 56 | F3: =TRUE() -> TRUE | G3: #3eb1d7 | H3: REGULAR | I3: 2
A4: 3 | B4: Notification Decision | C4: Project Notification | D4: EA Act (2018) | E4: 4 | F4: =TRUE() -> TRUE | G4: #3eb1d7 | H4: REGULAR | I4: 3

Sheet Events
A1: No | B1: Parent | C1: PhaseNo | D1: EventName | E1: Phase | F1: EventType | G1: EventCategory | H1: EventPosition | I1: MultipleDays | J1: StartAt | K1: NumberOfDays | L1: Visibility | M1: SortOrder
A2: 1 | C2: 1 | D2: Start of Intake Phase (e.g. Initial Contact, Draft Sharing, or PN Submission) | E2: =IF((C2=""),"",VLOOKUP(C2,Phases!$A$2:$B$4,2,FALSE())) -> Notification Intake | F2: Date Capture | G2: Milestone | H2: START | I2: =FALSE() -> FALSE | J2: 0 | K2: 0 | L2: MANDATORY | M2: 1
A3: 2 | C3: 1 | D3: Meeting with Proponent | E3: =IF((C3=""),"",VLOOKUP(C3,Phases!$A$2:$B$4,2,FALSE())) -> Notification Intake | F3: Meeting | G3: Milestone | H3: INTERMEDIATE | I3: =FALSE() -> FALSE | J3: 7 | K3: 0 | L3: SUGGESTED | M3: 2
A4: 3 | C4: 1 | D4: Additional Information Submission | E4: =IF((C4=""),"",VLOOKUP(C4,Phases!$A$2:$B$4,2,FALSE())) -> Notification Intake | F4: Submission | G4: Milestone | H4: INTERMEDIATE | I4: =FALSE() -> FALSE | J4: 0 | K4: 0 | L4: OPTIONAL | M4: 3
A5: 4 | C5: 1 | D5: Document Submitted to EAO for "Initial Review" | E5: =IF((C5=""),"",VLOOKUP(C5,Phases!$A$2:$B$4,2,FALSE())) -> Notification Intake | F5: Submission | G5: Milestone | H5: INTERMEDIATE | I5: =FALSE() -> FALSE | J5: 0 | K5: 0 | L5: OPTIONAL | M5: 4
A6: 5 | B6: 4 | C6: 1 | D6: EAO's Viewpoint on Submitted Document | E6: =IF((C6=""),"",VLOOKUP(C6,Phases!$A$2:$B$4,2,FALSE())) -> Notification Intake | F6: PAD (Lead) | G6: Decision | H6: INTERMEDIATE | I6: =FALSE() -> FALSE | J6: 7 | K6: 0 | L6: OPTIONAL | M6: 5
A7: 6 | C7: 1 | D7: Project Notification Withdrawn | E7: =IF((C7=""),"",VLOOKUP(C7,Phases!$A$2:$B$4,2,FALSE())) -> Notification Intake | F7: EPD | G7: Decision | H7: INTERMEDIATE | I7: =FALSE() -> FALSE | J7: 0 | K7: 0 | L7: OPTIONAL | M7: 6
A8: 7 | C8: 1 | D8: Direct Submission of Project Notification - DELETE this Intake Phase! | E8: =IF((C8=""),"",VLOOKUP(C8,Phases!$A$2:$B$4,2,FALSE())) -> Notification Intake | F8: PAD (Lead) | G8: Decision | H8: INTERMEDIATE | I8: =FALSE() -> FALSE | J8: 0 | K8: 0 | L8: OPTIONAL | M8: 7
A9: 8 | C9: 1 | D9: Other | E9: =IF((C9=""),"",VLOOKUP(C9,Phases!$A$2:$B$4,2,FALSE())) -> Notification Intake | F9: Other | G9: Milestone | H9: INTERMEDIATE | I9: =FALSE() -> FALSE | J9: 0 | K9: 0 | L9: OPTIONAL | M9: 8
A10: 9 | C10: 1 | D10: Last Day of Intake Phase (day before formal submission) | E10: =IF((C10=""),"",VLOOKUP(C10,Phases!$A$2:$B$4,2,FALSE())) -> Notification Intake | F10: Date Capture | G10: Milestone | H10: END | I10: =FALSE() -> FALSE | J10: 21 | K10: 0 | L10: MANDATORY | M10: 9
A11: 10 | C11: 2 | D11: Project Notification Submission Received (Day Zero) | E11: =IF((C11=""),"",VLOOKUP(C11,Phases!$A$2:$B$4,2,FALSE())) -> Notification Review | F11: Submission | G11: Milestone | H11: START | I11: =FALSE() -> FALSE | J11: 0 | K11: 0 | L11: MANDATORY | M11: 10
A12: 11 | C12: 2 | D12: Delegation of PN Decision | E12: =IF((C12=""),"",VLOOKUP(C12,Phases!$A$2:$B$4,2,FALSE())) -> Notification Review | F12: Minister | G12: Decision | H12: INTERMEDIATE | I12: =FALSE() -> FALSE | J12: 7 | K12: 0 | L12: MANDATORY | M12: 11
A13: 12 | C13: 2 | D13: Comment Period | E13: =IF((C13=""),"",VLOOKUP(C13,Phases!$A$2:$B$4,2,FALSE())) -> Notification Review | F13: Comment Period | G13: PCP | H13: INTERMEDIATE | I13: =TRUE() -> TRUE | J13: 14 | K13: 21 | L13: SUGGESTED | M13: 12
A14: 13 | B14: 12 | C14: 2 | D14: PCP Coming Soon Announcement & Tweet | E14: =IF((C14=""),"",VLOOKUP(C14,Phases!$A$2:$B$4,2,FALSE())) -> Notification Review | F14: Communications | G14: Calendar | H14: INTERMEDIATE | I14: =FALSE() -> FALSE | J14: -7 | K14: 0 | L14: MANDATORY | M14: 13
A15: 14 | B15: 12 | C15: 2 | D15: PCP Coming Soon Milestone Bullet | E15: =IF((C15=""),"",VLOOKUP(C15,Phases!$A$2:$B$4,2,FALSE())) -> Notification Review | F15: Executive | G15: Calendar | H15: INTERMEDIATE | I15: =FALSE() -> FALSE | J15: -7 | K15: 0 | L15: MANDATORY | M15: 14
A16: 15 | B16: 12 | C16: 2 | D16: PCP Now Open Announcement & Tweet | E16: =IF((C16=""),"",VLOOKUP(C16,Phases!$A$2:$B$4,2,FALSE())) -> Notification Review | F16: Communications | G16: Calendar | H16: INTERMEDIATE | I16: =FALSE() -> FALSE | J16: 0 | K16: 0 | L16: MANDATORY | M16: 15
A17: 16 | B17: 12 | C17: 2 | D17: PCP Ending Soon Announcement & Tweet | E17: =IF((C17=""),"",VLOOKUP(C17,Phases!$A$2:$B$4,2,FALSE())) -> Notification Review | F17: Communications | G17: Calendar | H17: INTERMEDIATE | I17: =FALSE() -> FALSE | J17: number_of_days-2 | K17: 0 | L17: MANDATORY | M17: 16
A18: 17 | C18: 2 | D18: Additional Information Submission | E18: =IF((C18=""),"",VLOOKUP(C18,Phases!$A$2:$B$4,2,FALSE())) -> Notification Review | F18: Submission | G18: Milestone | H18: INTERMEDIATE | I18: =FALSE() -> FALSE | J18: 0 | K18: 0 | L18: OPTIONAL | M18: 17
A19: 18 | C19: 2 | D19: GHG Threshold Information Note | E19: =IF((C19=""),"",VLOOKUP(C19,Phases!$A$2:$B$4,2,FALSE())) -> Notification Review | F19: Report | G19: Milestone | H19: INTERMEDIATE | I19: =FALSE() -> FALSE | J19: 0 | K19: 0 | L19: OPTIONAL | M19: 18
A20: 19 | B20: 18 | C20: 2 | D20: REMINDER: GHG Minister's Information Note | E20: =IF((C20=""),"",VLOOKUP(C20,Phases!$A$2:$B$4,2,FALSE())) -> Notification Review | F20: Executive | G20: Calendar | H20: INTERMEDIATE | I20: =FALSE() -> FALSE | J20: 0 | K20: 0 | L20: OPTIONAL | M20: 19
A21: 20 | C21: 2 | D21: Additional Comment Period | E21: =IF((C21=""),"",VLOOKUP(C21,Phases!$A$2:$B$4,2,FALSE())) -> Notification Review | F21: Comment Period | G21: PCP | H21: INTERMEDIATE | I21: =TRUE() -> TRUE | J21: 0 | K21: 30 | L21: OPTIONAL | M21: 20
A22: 21 | B22: 20 | C22: 2 | D22: PCP Coming Soon Announcement & Tweet | E22: =IF((C22=""),"",VLOOKUP(C22,Phases!$A$2:$B$4,2,FALSE())) -> Notification Review | F22: Communications | G22: Calendar | H22: INTERMEDIATE | I22: =FALSE() -> FALSE | J22: -7 | K22: 0 | L22: OPTIONAL | M22: 21
A23: 22 | B23: 20 | C23: 2 | D23: Additional PCP Milestone Bullet | E23: =IF((C23=""),"",VLOOKUP(C23,Phases!$A$2:$B$4,2,FALSE())) -> Notification Review | F23: Executive | G23: Calendar | H23: INTERMEDIATE | I23: =FALSE() -> FALSE | J23: -7 | K23: 0 | L23: OPTIONAL | M23: 22
A24: 23 | B24: 20 | C24: 2 | D24: PCP Now Open Announcement & Tweet | E24: =IF((C24=""),"",VLOOKUP(C24,Phases!$A$2:$B$4,2,FALSE())) -> Notification Review | F24: Communications | G24: Calendar | H24: INTERMEDIATE | I24: =FALSE() -> FALSE | J24: 0 | K24: 0 | L24: OPTIONAL | M24: 23
A25: 24 | B25: 20 | C25: 2 | D25: PCP Ending Soon Announcement & Tweet | E25: =IF((C25=""),"",VLOOKUP(C25,Phases!$A$2:$B$4,2,FALSE())) -> Notification Review | F25: Communications | G25: Calendar | H25: INTERMEDIATE | I25: =FALSE() -> FALSE | J25: number_of_days-2 | K25: 0 | L25: OPTIONAL | M25: 24
A26: 25 | C26: 2 | D26: Open House | E26: =IF((C26=""),"",VLOOKUP(C26,Phases!$A$2:$B$4,2,FALSE())) -> Notification Review | F26: Open House | G26: PCP | H26: INTERMEDIATE | I26: =FALSE() -> FALSE | J26: 0 | K26: 0 | L26: OPTIONAL | M26: 25
A27: 26 | C27: 2 | D27: Virtual Information Session | E27: =IF((C27=""),"",VLOOKUP(C27,Phases!$A$2:$B$4,2,FALSE())) -> Notification Review | F27: Virtual Information Session | G27: PCP | H27: INTERMEDIATE | I27: =FALSE() -> FALSE | J27: 0 | K27: 0 | L27: OPTIONAL | M27: 26
A28: 27 | C28: 2 | D28: Comment Period Time Limit Extension | E28: =IF((C28=""),"",VLOOKUP(C28,Phases!$A$2:$B$4,2,FALSE())) -> Notification Review | F28: PCP Time Limit Extension | G28: Extension | H28: INTERMEDIATE | I28: =FALSE() -> FALSE | J28: 0 | K28: 0 | L28: OPTIONAL | M28: 27
A29: 28 | B29: 27 | C29: 2 | D29: PCP Extended Announcement & Tweet | E29: =IF((C29=""),"",VLOOKUP(C29,Phases!$A$2:$B$4,2,FALSE())) -> Notification Review | F29: Communications | G29: Calendar | H29: INTERMEDIATE | I29: =FALSE() -> FALSE | J29: 0 | K29: 0 | L29: OPTIONAL | M29: 28
A30: 29 | B30: 27 | C30: 2 | D30: PCP Extended Milestone Bullet | E30: =IF((C30=""),"",VLOOKUP(C30,Phases!$A$2:$B$4,2,FALSE())) -> Notification Review | F30: Executive | G30: Calendar | H30: INTERMEDIATE | I30: =FALSE() -> FALSE | J30: 0 | K30: 0 | L30: OPTIONAL | M30: 29
A31: 30 | C31: 2 | D31: s.38 Extension of Time Limit | E31: =IF((C31=""),"",VLOOKUP(C31,Phases!$A$2:$B$4,2,FALSE())) -> Notification Review | F31: Time Limit Extension | G31: Extension | H31: INTERMEDIATE | I31: =FALSE() -> FALSE | J31: 0 | K31: 0 | L31: OPTIONAL | M31: 30
A32: 31 | B32: 30 | C32: 2 | D32: Extension Announcement & Tweet | E32: =IF((C32=""),"",VLOOKUP(C32,Phases!$A$2:$B$4,2,FALSE())) -> Notification Review | F32: Communications | G32: Calendar | H32: INTERMEDIATE | I32: =FALSE() -> FALSE | J32: 0 | K32: 0 | L32: OPTIONAL | M32: 31
A33: 32 | B33: 30 | C33: 2 | D33: Time Limit Extended Milestone Bullet | E33: =IF((C33=""),"",VLOOKUP(C33,Phases!$A$2:$B$4,2,FALSE())) -> Notification Review | F33: Executive | G33: Calendar | H33: INTERMEDIATE | I33: =FALSE() -> FALSE | J33: 0 | K33: 0 | L33: OPTIONAL | M33: 32
A34: 33 | C34: 2 | D34: s.45 Suspension of the Project Notification Process | E34: =IF((C34=""),"",VLOOKUP(C34,Phases!$A$2:$B$4,2,FALSE())) -> Notification Review | F34: Time Limit Suspension | G34: Suspension | H34: INTERMEDIATE | I34: =FALSE() -> FALSE | J34: 0 | K34: 0 | L34: OPTIONAL | M34: 33
A35: 34 | B35: 33 | C35: 2 | D35: Project Notification Process Suspension Announcement & Tweet | E35: =IF((C35=""),"",VLOOKUP(C35,Phases!$A$2:$B$4,2,FALSE())) -> Notification Review | F35: Communications | G35: Calendar | H35: INTERMEDIATE | I35: =FALSE() -> FALSE | J35: 0 | K35: 0 | L35: OPTIONAL | M35: 34
A36: 35 | B36: 33 | C36: 2 | D36: Project Notification Process Suspended Milestone Bullet | E36: =IF((C36=""),"",VLOOKUP(C36,Phases!$A$2:$B$4,2,FALSE())) -> Notification Review | F36: Executive | G36: Calendar | H36: INTERMEDIATE | I36: =FALSE() -> FALSE | J36: 0 | K36: 0 | L36: OPTIONAL | M36: 35
A37: 36 | C37: 2 | D37: s.45 Resumption of the Project Notification Process | E37: =IF((C37=""),"",VLOOKUP(C37,Phases!$A$2:$B$4,2,FALSE())) -> Notification Review | F37: Time Limit Resumption | G37: Suspension | H37: INTERMEDIATE | I37: =FALSE() -> FALSE | J37: 0 | K37: 0 | L37: OPTIONAL | M37: 36
A38: 37 | B38: 36 | C38: 2 | D38: Project Notification Process Resumption Announcement & Tweet | E38: =IF((C38=""),"",VLOOKUP(C38,Phases!$A$2:$B$4,2,FALSE())) -> Notification Review | F38: Communications | G38: Calendar | H38: INTERMEDIATE | I38: =FALSE() -> FALSE | J38: 0 | K38: 0 | L38: OPTIONAL | M38: 37
A39: 38 | B39: 36 | C39: 2 | D39: Project Notification Process Resumed Milestone Bullet | E39: =IF((C39=""),"",VLOOKUP(C39,Phases!$A$2:$B$4,2,FALSE())) -> Notification Review | F39: Executive | G39: Calendar | H39: INTERMEDIATE | I39: =FALSE() -> FALSE | J39: 0 | K39: 0 | L39: OPTIONAL | M39: 38
A40: 39 | C40: 2 | D40: Project Notification Terminated s.39(d) | E40: =IF((C40=""),"",VLOOKUP(C40,Phases!$A$2:$B$4,2,FALSE())) -> Notification Review | F40: CEAO | G40: Decision | H40: INTERMEDIATE | I40: =FALSE() -> FALSE | J40: 0 | K40: 0 | L40: OPTIONAL | M40: 39
...

Sheet Outcomes
A1: No | B1: TemplateNo | C1: TemplateName | D1: OutcomeName | E1: OutcomeDescription | F1: SortOrder
A2: 1 | B2: 5 | C2: =IF((B2=""),"",VLOOKUP(B2,Events!$A$2:$D$319,4,FALSE())) -> EAO's Viewpoint on Submitted Document | D2: EAO's Viewpoint is POSITIVE | F2: 1
A3: 2 | B3: 5 | C3: =IF((B3=""),"",VLOOKUP(B3,Events!$A$2:$D$319,4,FALSE())) -> EAO's Viewpoint on Submitted Document | D3: EAO's Viewpoint is NEGATIVE | F3: 2
A4: 3 | B4: 6 | C4: =IF((B4=""),"",VLOOKUP(B4,Events!$A$2:$D$319,4,FALSE())) -> Project Notification Withdrawn | D4: Proponent withdraws Submission from the Project Notification process | F4: 3
A5: 4 | B5: 7 | C5: =IF((B5=""),"",VLOOKUP(B5,Events!$A$2:$D$319,4,FALSE())) -> Direct Submission of Project Notification - DELETE this Intake Phase! | D5: Delete this "Intake Phase" and go directly to "Notification Review" | F5: 4
A6: 5 | B6: 10 | C6: =IF((B6=""),"",VLOOKUP(B6,Events!$A$2:$D$319,4,FALSE())) -> Project Notification Submission Received (Day Zero) | D6: Starts the 60-Day Legislated Time Period for Project Notification | F6: 5
A7: 6 | B7: 11 | C7: =IF((B7=""),"",VLOOKUP(B7,Events!$A$2:$D$319,4,FALSE())) -> Delegation of PN Decision | D7: Minister to make the Project Notification Decision | F7: 6
A8: 7 | B8: 11 | C8: =IF((B8=""),"",VLOOKUP(B8,Events!$A$2:$D$319,4,FALSE())) -> Delegation of PN Decision | D8: CEAO is delegated to make the Project Notification Decision | F8: 8
A9: 8 | B9: 39 | C9: =IF((B9=""),"",VLOOKUP(B9,Events!$A$2:$D$319,4,FALSE())) -> Project Notification Terminated s.39(d) | D9: Project Notification is Terminated under s.39(d) of Act | F9: 9
A10: 9 | B10: 42 | C10: =IF((B10=""),"",VLOOKUP(B10,Events!$A$2:$D$319,4,FALSE())) -> Project Withdrawn | D10: Proponent withdraws Submission from the Project Notification process | F10: 10
A11: 10 | B11: 60 | C11: =IF((B11=""),"",VLOOKUP(B11,Events!$A$2:$D$319,4,FALSE())) -> Project Notification Terminated s.39(d) | D11: Project Notification is Terminated under s.39(d) of Act | F11: 11
A12: 11 | B12: 63 | C12: =IF((B12=""),"",VLOOKUP(B12,Events!$A$2:$D$319,4,FALSE())) -> Project Withdrawn | D12: Proponent withdraws Submission from the Project Notification process | F12: 12
A13: 12 | B13: 67 | C13: =IF((B13=""),"",VLOOKUP(B13,Events!$A$2:$D$319,4,FALSE())) -> Decision: Project Notification | D13: No Further Review Required | F13: 13
... A16: 15 | B16: 11 | C16: =IF((B16=""),"",VLOOKUP(B16,Events!$A$2:$D$319,4,FALSE())) -> Delegation of PN Decision | D16: Deputy CEAO is delegated to make the Project Notification Decision | F16: 7

Sheet Actions
A1: No | B1: OutcomeNo | C1: OutcomeName | D1: ActionName | E1: ActionDescription | F1: AdditionalParams | G1: SortOrder
A2: 1 | B2: 3 | C2: =IF((B2=""),"",VLOOKUP(B2,Outcomes!$A$2:$D$15,4,FALSE())) -> Proponent withdraws Submission from the Project Notification process | D2: SetPhasesStatus | E2: Set all "future" PHASEs to INACTIVE | F2: {"all_future_phases": false} | G2: 1
A3: 2 | B3: 3 | C3: =IF((B3=""),"",VLOOKUP(B3,Outcomes!$A$2:$D$15,4,FALSE())) -> Proponent withdraws Submission from the Project Notification process | D3: SetEventsStatus | E3: Set all "future" EVENTs in thisPhase to INACTIVE | F3: {"all_future_events": false} | G3: 2
A4: 3 | B4: 3 | C4: =IF((B4=""),"",VLOOKUP(B4,Outcomes!$A$2:$D$15,4,FALSE())) -> Proponent withdraws Submission from the Project Notification process | D4: SetWorkState | E4: Set workState to WITHDRAWN | F4: {"work_state": "WITHDRAWN"} | G4: 3
A5: 4 | B5: 3 | C5: =IF((B5=""),"",VLOOKUP(B5,Outcomes!$A$2:$D$15,4,FALSE())) -> Proponent withdraws Submission from the Project Notification process | D5: SetProjectStatus | E5: Set projectActive to FALSE | F5: {"is_active": false} | G5: 4
A6: 5 | B6: 4 | C6: =IF((B6=""),"",VLOOKUP(B6,Outcomes!$A$2:$D$15,4,FALSE())) -> Delete this "Intake Phase" and go directly to "Notification Review" | D6: SetEventDate | E6: Set "Notification Review | Project Notification Submission Received (Day Zero)" ANTICIPATED to thisActual + 0 | F6: {"phase_name":"Notification Review","work_type_id": 1, "ea_act_id": 3, "event_name": "Project Notification Submission Received (Day Zero)", "start_at": 0 } | G6: 5
A7: 6 | B7: 4 | C7: =IF((B7=""),"",VLOOKUP(B7,Outcomes!$A$2:$D$15,4,FALSE())) -> Delete this "Intake Phase" and go directly to "Notification Review" | D7: SetEventsStatus | E7: Set all "future" EVENTs in thisPhase to INACTIVE | F7: {"all_future_events": false} | G7: 6
A8: 7 | B8: 4 | C8: =IF((B8=""),"",VLOOKUP(B8,Outcomes!$A$2:$D$15,4,FALSE())) -> Delete this "Intake Phase" and go directly to "Notification Review" | D8: SetPhasesStatus | E8: Set thisPhase to INACTIVE | F8: [{"phase_name":"Notification Intake","work_type_id": 1, "ea_act_id": 3, "is_active": false }] | G8: 7
A9: 8 | B9: 5 | C9: =IF((B9=""),"",VLOOKUP(B9,Outcomes!$A$2:$D$15,4,FALSE())) -> Starts the 60-Day Legislated Time Period for Project Notification | D9: LockWorkStartDate | E9: Set thisWorkStartDate to thisEventACTUAL | F9: {"start_date_locked": true} | G9: 8
A10: 9 | B10: 6 | C10: =IF((B10=""),"",VLOOKUP(B10,Outcomes!$A$2:$D$15,4,FALSE())) -> Minister to make the Project Notification Decision | D10: SetWorkDecisionMaker | E10: Set thisWorkDecisionMaker to currentMinisterEnvironment | F10: {"position_id": 8} | G10: 9
A11: 10 | B11: 7 | C11: =IF((B11=""),"",VLOOKUP(B11,Outcomes!$A$2:$D$15,4,FALSE())) -> CEAO is delegated to make the Project Notification Decision | D11: SetWorkDecisionMaker | E11: Set thisWorkDecisionMaker to currentCEAO | F11: {"position_id": 1} | G11: 10
A12: 11 | B12: 8 | C12: =IF((B12=""),"",VLOOKUP(B12,Outcomes!$A$2:$D$15,4,FALSE())) -> Project Notification is Terminated under s.39(d) of Act | D12: SetPhasesStatus | E12: Set all "future" PHASEs to INACTIVE | F12: {"all_future_phases": false} | G12: 12
A13: 12 | B13: 8 | C13: =IF((B13=""),"",VLOOKUP(B13,Outcomes!$A$2:$D$15,4,FALSE())) -> Project Notification is Terminated under s.39(d) of Act | D13: SetEventsStatus | E13: Set all "future" EVENTs in thisPhase to INACTIVE | F13: {"all_future_events": false} | G13: 13
... A34: 33 | B34: 14 | C34: =IF((B34=""),"",VLOOKUP(B34,Outcomes!$A$2:$D$15,4,FALSE())) -> Project Referred to Minister for Designation (s.11) | D34: CreateWork | E34: createWork: "Minister's Designation" and link to thisWorkLinkedProject | F34: {"work_type": 2} | G34: 34
A35: 34 | B35: 15 | C35: =IF((B35=""),"",VLOOKUP(B35,Outcomes!$A$2:$D$25,4,FALSE())) -> Deputy CEAO is delegated to make the Project Notification Decision | D35: SetWorkDecisionMaker | E35: Set the workDecisionMaker to currentADM | F35: {"position_id": 2} | G35: 11

Sheet Lookups
B2: WorkType | D2: EA Act | F2: Legislated | I2: Event Type | K2: Event Category | M2: Visibility | O2: ActionName | Q2: Event Position | S2: Multiple Days | U2: Action Name
B3: Project Notification | D3: EA Act (2018) | F3: =TRUE() -> TRUE | H3: Milestone | I3: Generic | K3: Milestone | M3: MANDATORY | O3: AllEventsDeactivated | Q3: START | S3: =TRUE() -> TRUE | U3: AddEvent
B4: Minister's Designation | D4: EA Act (2002) | F4: =FALSE() -> FALSE | H4: Milestone | I4: Meeting | K4: Calendar | M4: SUGGESTED | O4: AllEventsDeleted | Q4: INTERMEDIATE | S4: =FALSE() -> FALSE | U4: AddPhase
B5: CEAO's Designation | D5: EA Act (1996) | H5: Milestone | I5: Notification | K5: Decision | M5: OPTIONAL | O5: CloseEverything | Q5: END | U5: ChangePhaseEndEvent
B6: EAC Assessment | H6: Milestone | I6: Order | K6: Finance | M6: HIDDEN | O6: CloseWork | U6: CreateWork
B7: Exemption Request | H7: Milestone | I7: Referral | K7: PCP | O7: CompleteCurrentPhase | U7: LockWorkStartDate
B8: Dispute Resolution | H8: Milestone | I8: Report | K8: Extension | O8: CreateNewWork | U8: SetEventDate
B9: EAC/Order Amendment | H9: Milestone | I9: Request | K9: Suspension | O9: DisableWorkStartDate | U9: SetEventStatus
B10: Document Review | H10: Milestone | I10: Submission | O10: DuplicatePhase | U10: SetFederalInvolvement
B11: EAC Extension | H11: Milestone | I11: Other | U11: SetPhaseStatus
B12: Substantial Start Decision | H12: Milestone | I12: Date Capture | U12: SetProjectState
B13: EAC/Order Transfer | H13: Extension | I13: Time Limit Extension | U13: SetProjectStatus
B14: EAC/Order Suspension | H14: Extension | I14: PCP Time Limit Extension | U14: SetWorkDecisionMaker
B15: EAC/Order Cancellation | H15: Suspension | I15: Time Limit Suspension | U15: SetWorkState
B16: Other | H16: Suspension | I16: Time Limit Resumption
H17: Decision | I17: EAC Ministers
H18: Decision | I18: Minister
H19: Decision | I19: CEAO
H20: Decision | I20: ADM
H21: Decision | I21: EPD
H22: Decision | I22: PAD (Lead)
H23: Decision | I23: Reviewer
H24: Decision | I24: Federal
H25: Decision | I25: Other
H26: PCP | I26: Comment Period
H27: PCP | I27: Open House
H28: PCP | I28: Virtual Information Session
... H39: Finance | I39: Other
